[0m16:41:04.850935 [debug] [MainThread]: Sending event: {'category': 'dbt', 'action': 'invocation', 'label': 'start', 'context': [<snowplow_tracker.self_describing_json.SelfDescribingJson object at 0x0000024D5F5412B0>, <snowplow_tracker.self_describing_json.SelfDescribingJson object at 0x0000024D5D155D10>, <snowplow_tracker.self_describing_json.SelfDescribingJson object at 0x0000024D60008190>]}


============================== 16:41:04.874244 | f4e260dd-4aca-4bcd-9a4f-11f7a959a5ca ==============================
[0m16:41:04.874244 [info ] [MainThread]: Running with dbt=1.10.13
[0m16:41:04.875214 [debug] [MainThread]: running dbt with arguments {'partial_parse': 'True', 'write_json': 'True', 'send_anonymous_usage_stats': 'True', 'warn_error': 'None', 'cache_selected_only': 'False', 'target_path': 'None', 'use_colors': 'True', 'invocation_command': 'dbt init gdp_dbt_project', 'log_format': 'default', 'version_check': 'True', 'introspect': 'True', 'debug': 'False', 'printer_width': '80', 'fail_fast': 'False', 'no_print': 'None', 'use_experimental_parser': 'False', 'empty': 'None', 'log_cache_events': 'False', 'quiet': 'False', 'indirect_selection': 'eager', 'log_path': 'logs', 'profiles_dir': 'C:\\Users\\PC\\.dbt', 'warn_error_options': 'WarnErrorOptionsV2(error=[], warn=[], silence=[])', 'static_parser': 'True'}
[0m16:41:04.909644 [info ] [MainThread]: Creating dbt configuration folder at C:\Users\PC\.dbt
[0m16:41:04.912152 [debug] [MainThread]: Starter project path: D:\Python_Projects\Sku_Challenge\venv\Lib\site-packages\dbt\include\starter_project
[0m16:41:04.933407 [info ] [MainThread]: 
Your new dbt project "gdp_dbt_project" was created!

For more information on how to configure the profiles.yml file,
please consult the dbt documentation here:

  https://docs.getdbt.com/docs/configure-your-profile

One more thing:

Need help? Don't hesitate to reach out to us via GitHub issues or on Slack:

  https://community.getdbt.com/

Happy modeling!

[0m16:41:04.934013 [info ] [MainThread]: Setting up your profile.
[0m16:44:29.551703 [error] [MainThread]: Encountered an error:

[0m16:44:29.554832 [error] [MainThread]: Traceback (most recent call last):
  File "D:\Python_Projects\Sku_Challenge\venv\Lib\site-packages\dbt\cli\requires.py", line 178, in wrapper
    result, success = func(*args, **kwargs)
                      ~~~~^^^^^^^^^^^^^^^^^
  File "D:\Python_Projects\Sku_Challenge\venv\Lib\site-packages\dbt\cli\requires.py", line 128, in wrapper
    return func(*args, **kwargs)
  File "D:\Python_Projects\Sku_Challenge\venv\Lib\site-packages\dbt\cli\main.py", line 483, in init
    results = task.run()
  File "D:\Python_Projects\Sku_Challenge\venv\Lib\site-packages\dbt\task\init.py", line 346, in run
    self.setup_profile(profile_name)
    ~~~~~~~~~~~~~~~~~~^^^^^^^^^^^^^^
  File "D:\Python_Projects\Sku_Challenge\venv\Lib\site-packages\dbt\task\init.py", line 262, in setup_profile
    self.create_profile_from_target(adapter, profile_name=profile_name)
    ~~~~~~~~~~~~~~~~~~~~~~~~~~~~~~~^^^^^^^^^^^^^^^^^^^^^^^^^^^^^^^^^^^^
  File "D:\Python_Projects\Sku_Challenge\venv\Lib\site-packages\dbt\task\init.py", line 179, in create_profile_from_target
    self.create_profile_from_profile_template(profile_template, profile_name)
    ~~~~~~~~~~~~~~~~~~~~~~~~~~~~~~~~~~~~~~~~~^^^^^^^^^^^^^^^^^^^^^^^^^^^^^^^^
  File "D:\Python_Projects\Sku_Challenge\venv\Lib\site-packages\dbt\task\init.py", line 163, in create_profile_from_profile_template
    target = self.generate_target_from_input(prompts, initial_target)
  File "D:\Python_Projects\Sku_Challenge\venv\Lib\site-packages\dbt\task\init.py", line 129, in generate_target_from_input
    target[key] = click.prompt(
                  ~~~~~~~~~~~~^
        text, default=default, hide_input=hide_input, type=type
        ^^^^^^^^^^^^^^^^^^^^^^^^^^^^^^^^^^^^^^^^^^^^^^^^^^^^^^^
    )
    ^
  File "D:\Python_Projects\Sku_Challenge\venv\Lib\site-packages\click\termui.py", line 168, in prompt
    value = prompt_func(prompt)
  File "D:\Python_Projects\Sku_Challenge\venv\Lib\site-packages\click\termui.py", line 151, in prompt_func
    raise Abort() from None
click.exceptions.Abort

[0m16:44:29.556650 [debug] [MainThread]: Command `dbt init` failed at 16:44:29.556486 after 204.83 seconds
[0m16:44:29.557012 [debug] [MainThread]: Sending event: {'category': 'dbt', 'action': 'invocation', 'label': 'end', 'context': [<snowplow_tracker.self_describing_json.SelfDescribingJson object at 0x0000024D618649D0>, <snowplow_tracker.self_describing_json.SelfDescribingJson object at 0x0000024D61851250>, <snowplow_tracker.self_describing_json.SelfDescribingJson object at 0x0000024D616FDE10>]}
[0m16:44:29.557345 [debug] [MainThread]: Flushing usage events
[0m16:44:30.840197 [debug] [MainThread]: An error was encountered while trying to flush usage events
